<mujoco model="reacher">
	<compiler angle="radian" inertiafromgeom="true"/>

	<default>
		<joint armature="1" damping="1" limited="true"/>
		<geom contype="0" friction="3 0.1 0.1" rgba="0.7 0.8 0 1"/>
	</default>

	<option gravity="0 0 -9.81" integrator="RK4" timestep="0.01"/>

	<worldbody>
		
		<!-- Arena -->
		<geom conaffinity="0" contype="0" name="ground" pos="0 0.5 0" rgba="0.9 0.9 0.9 1" size="1 1 10" type="plane"/>

		<geom conaffinity="1" fromto="-0.16 -0.25  .01   0.16  -0.25  .01" name="sideS" rgba="0.0 0.0 0.0 1" size=".02" type="capsule"/>
		<geom conaffinity="1" fromto=" 0.16 -0.25  .01   0.16   0.0   .01" name="sideE" rgba="0.0 0.0 0.0 1" size=".02" type="capsule"/>
		<geom conaffinity="1" fromto="-0.16 -0.25  .01  -0.16   0.0   .01" name="sideW" rgba="0.0 0.0 0.0 1" size=".02" type="capsule"/>
		

		<!-- Starting point -->
		<geom conaffinity="0" contype="0" pos="0 0 0.01" name="root" rgba="0.0 0.2 0.9 0.2" size=".025 .01" type="cylinder"/>

		<!-- Arm -->
		<body name="body0" pos="0 -0.22 .01">

			<geom fromto="0 0 0 0 0.15 0" name="link0" rgba="0.7 0.0 0.0 1" size=".01" type="capsule"/>
			<joint axis="0 0 1" limited="true" name="joint0" pos="0 0 0" range="-1.57 1.57" type="hinge" damping="1" stiffness="0" />

			<body name="body1" pos="0 0.15 0">
				<joint axis="0 0 1" limited="true" name="joint1" pos="0 0 0" range="-3.14 3.14" type="hinge" damping="1" stiffness="0" />
				<geom fromto="0 0 0 0 0.15 0" name="link1" rgba="0.8 0.7 0.7 1" size=".01" type="capsule"/>

				<body name="fingertip" pos="0 0.16 0">
					<geom contype="1" name="fingertip" pos="0 0 0" rgba="0.9 0.2 0.2 1" size=".01" type="sphere"/>
				</body>

			</body>

		</body>


		<!-- PUCK -->
		<body name="ball" pos="0 0 0.01">
            <geom name="ball" conaffinity="3" contype="2" pos="0 0 0" rgba="0.0 0.2 0.9 1" size=".025 .01" type="cylinder"/>
			<joint name="ball_x" type="slide" armature="1" axis="1 0 0" limited="false" pos="0 0 0" damping="1" stiffness="0" />
			<joint name="ball_y" type="slide" armature="1" axis="0 1 0" limited="false" pos="0 0 0" damping="1" stiffness="0" />
		</body>

		<!-- BALL -->
<!-- 		
		<body name="ball" pos="0.10 -0.10 0.0">
			<joint armature="1" axis="1 0 0" limited="false" name="ball_x" pos="0 0 0" ref=".1" type="slide" damping="1" stiffness="0" />
			<joint armature="1" axis="0 1 0" limited="false" name="ball_y" pos="0 0 0" ref="-.1" type="slide" damping="1" stiffness="0" />
			<geom conaffinity="3" contype="2" name="ball" pos="0 0 0" rgba="0.0 0.2 0.9 1" size=".025" type="sphere"/>
		</body>
-->

		<!-- Target -->
		<body name="real_target" pos="0.10 -0.10 0.0">
			<joint armature="1" axis="1 0 0" limited="true" name="real_target_x" pos="0 0 0" range="-2.9 2.9" ref=".1" type="slide" damping="0.1" stiffness="0" />
			<joint armature="1" axis="0 1 0" limited="true" name="real_target_y" pos="0 0 0" range="-2.9 2.9" ref="-.1" type="slide" damping="0.1" stiffness="0" />
			<geom conaffinity="0" contype="0" pos="0 0 0" name="real_target" rgba="0.0 0.8 0.5 0.2" size=".025 .01" type="cylinder"/>
		</body>


	</worldbody>


	<actuator>
		<position ctrllimited="true" ctrlrange="-100.0 100.0" gear="10.0" joint="joint0"/>
		<position ctrllimited="true" ctrlrange="-300.0 300.0" gear="10.0" joint="joint1"/>
	</actuator>


</mujoco>